new.py:89: RuntimeWarning: invalid value encountered in greater
  a = (data1[i][2] > thres_distance)*1
new.py:175: RuntimeWarning: invalid value encountered in greater
  a = (data1[i][2] > thres_distance)*1
new.py:218: RuntimeWarning: invalid value encountered in greater
  a = (data1_t[i][2] > thres_distance)*1
2017-12-01 15:06:42.156618: I tensorflow/core/common_runtime/gpu/gpu_device.cc:1031] Found device 0 with properties: 
name: Tesla K40t major: 3 minor: 5 memoryClockRate(GHz): 0.8755
pciBusID: 0000:82:00.0
totalMemory: 11.92GiB freeMemory: 11.85GiB
2017-12-01 15:06:42.156650: I tensorflow/core/common_runtime/gpu/gpu_device.cc:1121] Creating TensorFlow device (/device:GPU:0) -> (device: 0, name: Tesla K40t, pci bus id: 0000:82:00.0, compute capability: 3.5)
2017-12-01 15:24:27.612391: W tensorflow/core/framework/op_kernel.cc:1192] Not found: ; No such file or directory
Traceback (most recent call last):
  File "new.py", line 762, in <module>
    save_path = saver.save(sess,'model300_reweigh_loss_%s_%s.ckpt' %(epoch,int(100*np.mean(val_acc))))
  File "/app/tensorflow/1.4/lib/python2.7/site-packages/tensorflow/python/training/saver.py", line 1611, in save
    raise exc
ValueError: Parent directory of model300_reweigh_loss_0_91.ckpt doesn't exist, can't save.
