new.py:129: RuntimeWarning: invalid value encountered in greater
  a = (data1[i][2] > thres_distance)*1
new.py:260: RuntimeWarning: invalid value encountered in greater
  a = (data1_t[i][2] > thres_distance)*1
Traceback (most recent call last):
  File "new.py", line 609, in <module>
    conv2_diag = conv2d(conv2,weights['2_diag'],biases['2_diag'],reslu=False)
TypeError: conv2d() got an unexpected keyword argument 'reslu'
